Workbook

Sheet Dashboard
A1: The Great Race Dashboard
A2: Summary of 2,879 entries across 63 race years in the main Great Race results.
A4: Race years 63 | C4: Entries 2,879 | E4: Unique drivers 1,380 | G4: DNF/non-finish rate 41.1% | J4: Top manufacturer Holden | L4: Fastest winner avg speed 167.6 kph (2024)
A8: Key tables | J8: Driver starts by event group
A9: Top manufacturers by wins | B9: Wins | D9: Top drivers by starts | E9: Starts | G9: Top drivers by wins | H9: Wins | J9: Driver | K9: 1960-62 | L9: 1963-2025 | M9: 1997-99 ST | N9: 12 Hour | O9: 24 Hour | P9: Grand Total
A10: Holden | B10: 36 | D10: Jim Richards | E10: 34 | G10: Peter Brock | H10: 9 | J10: {=_xlfn.TAKE(_xlfn.SORTBY(_xlfn._xlws.FILTER('Dashboard Data'!U2:AA3000,'Dashboard Data'!U2:U3000<>""),_xlfn._xlws.FILTER('Dashboard Data'!AA2:AA3000,'Dashboard Data'!U2:U3000<>""),-1,_xlfn._xlws.FILTER('Dashboard Data'!U2:U3000,'Dashboard Data'!U2:U3000<>""),1),10)}
A11: Ford | B11: 21 | D11: Peter Brock | E11: 33 | G11: Craig Lowndes | H11: 7
A12: Chevrolet | B12: 2 | D12: Craig Lowndes | E12: 32 | G12: Garth Tander | H12: 6
A13: Nissan | B13: 2 | D13: Allan Grice | E13: 30 | G13: Jim Richards | H13: 6
A14: Jaguar | B14: 1 | D14: Colin Bond | E14: 28 | G14: Larry Perkins | H14: 6
A15: Morris | B15: 1 | D15: Dick Johnson | E15: 28 | G15: Mark Skaife | H15: 6
D16: John Bowe | E16: 28 | G16: Steven Richards | H16: 5
D17: Bob Holden | E17: 27 | G17: Allan Moffat | H17: 4
D18: Bruce Stewart | E18: 27 | G18: Greg Murphy | H18: 4
D19: Garth Tander | E19: 27 | G19: Jamie Whincup | H19: 4

Sheet Drivers in each year
A1: 1960 | C1: 1961 | E1: 1962 | G1: 1963 | I1: 1964 | K1: 1965 | M1: 1966 | O1: 1967 | Q1: 1968 | S1: 1988 | U1: 1989 | W1: 1990 | Y1: 1991 | AA1: 1992 | AC1: 1993 | AE1: 1994 | AG1: 1995 | AI1: 1996 | AK1: 1997 | AM1: 1998 | AO1: 1999 | AQ1: 2000 | AS1: 2001 | AU1: 2002 | AW1: 2003 | AY1: 2004 | BA1: 2005 | BC1: 2006 | BE1: 2007 | BG1: 2008 | BI1: 2009 | BK1: 2010 | BM1: 2011 | BO1: 2012 | BQ1: 2013 | BS1: 2014 | BU1: 2015 | BW1: 2016 | BY1: 2017 | CA1: 2018 | CC1: 2019 | CE1: 2020 | CG1: 2021 | CI1: 2022 | CK1: 2023 | CM1: 2024 | CO1: 2025
A2: Ern | B2: Abbott | C2: Dave | D2: Anderson | E2: Don | F2: Algie | G2: Ern | H2: Abbott | I2: Arnold | J2: Ahrenfeld | K2: Ern | L2: Abbott | M2: Rauno | N2: Aaltonen | O2: Lindsay | P2: Adcock | Q2: Lindsay | R2: Adcock | S2: Jeff | T2: Allam | U2: Michael | V2: Adcock | W2: Jeff | X2: Allam | Y2: Rauno | Z2: Aaltonen | AA2: Trevor | AB2: Ashby | AC2: Jeff | AD2: Allam | AE2: Jeff | AF2: Allam | AG2: Trevor | AH2: Ashby | AI2: Trevor | AJ2: Ashby | AK2: Trevor | AL2: Ashby | AM2: Trevor | AN2: Ashby | AO2: Trevor | AP2: Ashby | AQ2: Trevor | AR2: Ashby | AS2: Marcos | AT2: Ambrose | AU2: Marcos | AV2: Ambrose | AW2: Marcos | AX2: Ambrose | AY2: Marcos | AZ2: Ambrose | BA2: Marcos | BB2: Ambrose | BC2: Craig | BD2: Baird | BE2: Craig | BF2: Baird | BG2: Craig | BH2: Baird | BI2: Damian | BJ2: Assaillit | BK2: Damian | BL2: Assaillit | BM2: Craig | BN2: Baird | BO2: Craig | BP2: Baird | BQ2: Craig | BR2: Baird | BS2: Craig | BT2: Baird | BU2: Marcos | BV2: Ambrose | BW2: Craig | BX2: Baird | BY2: Tim | BZ2: Blanchard | CA2: Earl | CB2: Bamber | CC2: Tim | CD2: Blanchard | CE2: Tim | CF2: Blanchard | CG2: Zak | CH2: Best | CI2: Zak | CJ2: Best | CK2: Kai | CL2: Allen | CM2: Kai | CN2: Allen | CO2: Kai | CP2: Allen
A3: John | B3: Amp | C3: Norm | D3: Beechey | E3: Terry | F3: Allen | G3: John | H3: Alexander | I3: Tony | J3: Allen | K3: Arnold | L3: Ahrenfeld | M3: Ern | N3: Abbott | O3: Murray | P3: Bailey | Q3: Barry | R3: Arentz | S3: John | T3: Andretti | U3: Jeff | V3: Allam | W3: Trevor | X3: Ashby | Y3: Arthur | Z3: Abrahams | AA3: Scott | AB3: Bargwanna | AC3: Trevor | AD3: Ashby | AE3: Trevor | AF3: Ashby | AG3: David | AH3: Attard | AI3: David | AJ3: Attard | AK3: Bill | AL3: Attard | AM3: Bill | AN3: Attard | AO3: Bill | AP3: Attard | AQ3: Bill | AR3: Attard | AS3: Trevor | AT3: Ashby | AU3: Craig | AV3: Baird | AW3: Craig | AX3: Baird | AY3: Craig | AZ3: Baird | BA3: Craig | BB3: Baird | BC3: Jason | BD3: Bargwanna | BE3: Jason | BF3: Bargwanna | BG3: Jason | BH3: Bargwanna | BI3: Craig | BJ3: Baird | BK3: Craig | BL3: Baird | BM3: Jason | BN3: Bargwanna | BO3: David | BP3: Besnard | BQ3: Tim | BR3: Blanchard | BS3: Tim | BT3: Blanchard | BU3: Tim | BV3: Blanchard | BW3: Tim | BX3: Blanchard | BY3: Jason | BZ3: Bright | CA3: Tim | CB3: Blanchard | CC3: Will | CD3: Brown | CE3: Jordan | CF3: Boys | CG3: Tim | CH3: Blanchard | CI3: Tim | CJ3: Blanchard | CK3: Zak | CL3: Best | CM3: Jordan | CN3: Boys | CO3: Zach | CP3: Bates
A4: David | B4: Anderson | C4: Peter | D4: Boyd-Squires | E4: Jack | F4: Anderson | G4: Tony | H4: Allen | I4: Lionel | J4: Ayers | K4: Barry | L4: Arentz | M4: Barry | N4: Arentz | O4: Kevin | P4: Bartlett | Q4: Lionel | R4: Ayers | S4: Trevor | T4: Ashby | U4: Trevor | V4: Ashby | W4: Andrew | X4: Bagnall | Y4: Trevor | Z4: Ashby | AA4: Jason | AB4: Bargwanna | AC4: Neal | AD4: Bates | AE4: George | AF4: Ayoub | AG4: Ron | AH4: Barnacle | AI4: Bill | AJ4: Attard | AK4: Craig | AL4: Baird | AM4: Jason | AN4: Bargwanna | AO4: Craig | AP4: Baird | AQ4: Craig | AR4: Baird | AS4: Craig | AT4: Baird | AU4: Jason | AV4: Bargwanna | AW4: Jason | AX4: Bargwanna | AY4: Jason | AZ4: Bargwanna | BA4: Jason | BB4: Bargwanna | BC4: David | BD4: Besnard | BE4: David | BF4: Besnard | BG4: David | BH4: Besnard | BI4: Jason | BJ4: Bargwanna | BK4: Jason | BL4: Bargwanna | BM4: David | BN4: Besnard | BO4: Tim | BP4: Blanchard | BQ4: Jeroen | BR4: Bleekemolen | BS4: Jason | BT4: Bright | BU4: Sébastien | BV4: Bourdais | BW4: Jason | BX4: Bright | BY4: Matt | BZ4: Campbell | CA4: Jason | CB4: Bright | CC4: Dean | CD4: Canto | CE4: Will | CF4: Brown | CG4: Will | CH4: Brown | CI4: Jordan | CJ4: Boys | CK4: Tim | CL4: Blanchard | CM4: Will | CN4: Brown | CO4: Zak | CP4: Best
A5: Norm | B5: Beechey | C5: Albert | D5: Bridge | E5: David | F5: Anderson | G5: Arthur | H5: Andrews | I5: Lex | J5: Bailey | K5: Phil | L5: Barnes | M5: Lionel | N5: Ayers | O5: Bob | P5: Beasley | Q5: Kevin | R5: Bartlett | S5: Andrew | T5: Bagnall | U5: Reda | V5: Awadallah | W5: Craig | X5: Baird | Y5: Reda | Z5: Awadullah | AA5: Chris | AB5: Barns | AC5: Frank | AD5: Binding | AE5: Craig | AF5: Baird | AG5: Stephen | AH5: Bell | AI5: Kerry | AJ5: Baily | AK5: Jason | AL5: Bargwanna | AM5: Neal | AN5: Bates | AO5: Jason | AP5: Bargwanna | AQ5: Jason | AR5: Bargwanna | AS5: Jason | AT5: Bargwanna | AU5: Rick | AV5: Bates | AW5: Rick | AX5: Bates | AY5: David | AZ5: Besnard | BA5: David | BB5: Besnard | BC5: John | BD5: Bowe | BE5: John | BF5: Bowe | BG5: Jason | BH5: Bright | BI5: Troy | BJ5: Bayliss | BK5: David | BL5: Besnard | BM5: Tim | BN5: Blanchard | BO5: Jason | BP5: Bright | BQ5: Jason | BR5: Bright | BS5: Alex | BT5: Buncombe | BU5: Jason | BV5: Bright | BW5: Matt | BX5: Campbell | BY5: Dean | BZ5: Canto | CA5: Will | CB5: Brown | CC5: Michael | CD5: Caruso | CE5: Michael | CF5: Caruso | CG5: Matt | CH5: Campbell | CI5: Will | CJ5: Brown | CK5: Jordan | CL5: Boys | CM5: Aaron | CN5: Cameron | CO5: Jordan | CP5: Boys
A6: Ken | B6: Brigden | C6: Ken | D6: Brigden | E6: Norm | F6: Beechey | G6: Kevin | H6: Bartlett | I6: Phil | J6: Barnes | K6: Bill | L6: Barnett | M6: Malcolm | N6: Bailey | O6: Damon | P6: Beck | Q6: Tony | R6: Basile | S6: Kerry | T6: Baily | U6: Andrew | V6: Bagnall | W6: Jason | X6: Bargwanna | Y6: Dave | Z6: Barrow | AA6: Neal | AB6: Bates | AC6: John | AD6: Blanchard | AE6: Jeff | AF6: Barnes | AG6: John | AH6: Bowe | AI6: Ron | AJ6: Barnacle | AK6: Ron | AL6: Barnacle | AM6: G | AN6: Baxter | AO6: Ron | AP6: Barnacle | AQ6: Rick | AR6: Bates | AS6: Rick | AT6: Bates | AU6: Neal | AV6: Bates | AW6: Neal | AX6: Bates | AY6: John | AZ6: Bowe | BA6: John | BB6: Bowe | BC6: David | BD6: Brabham | BE6: Michael | BF6: Caruso | BG6: Dean | BH6: Canto | BI6: David | BJ6: Besnard | BK6: David | BL6: Brabham | BM6: David | BN6: Brabham | BO6: Dean | BP6: Canto | BQ6: Ryan | BR6: Briscoe | BS6: Dean | BT6: Canto | BU6: Alex | BV6: Buncombe | BW6: Dean | BX6: Canto | BY6: Michael | BZ6: Caruso | CA6: Dean | CB6: Canto | CC6: Fabian | CD6: Coulthard | CE6: Fabian | CF6: Coulthard | CG6: Michael | CH6: Caruso | CI6: Matthew | CJ6: Campbell | CK6: Will | CL6: Brown | CM6: Michael | CN6: Caruso | CO6: Will | CP6: Brown
A7: Bob | B7: Brown | C7: John | D7: Brindley | E7: Ann | F7: Bennett | G7: Warren | H7: Blomfield | I7: Bill | J7: Barnett | K7: Kevin | L7: Bartlett | M7: Kevin | N7: Bartlett | O7: Chris | P7: Brauer | Q7: Bob | R7: Beasley | S7: Dave | T7: Barrow | U7: Kevin | V7: Bartlett | W7: Dave | X7: Barrow | Y7: Neal | Z7: Bates | AA7: Rick | AB7: Bates | AC7: Colin | AD7: Bond | AE7: Stephen | AF7: Bell | AG7: Peter | AH7: Brock | AI7: Stephen | AJ7: Bell | AK7: Stephen | AL7: Bell | AM7: Shane | AN7: Beikoff | AO7: Neal | AP7: Bates | AQ7: Neal | AR7: Bates | AS7: David | AT7: Besnard | AU7: Daryl | AV7: Beattie | AW7: David | AX7: Besnard | AY7: David | AZ7: Brabham | BA7: David | BB7: Brabham | BC7: Dale | BD7: Brede | BE7: Fabian | BF7: Coulthard | BG7: Michael | BH7: Caruso | BI7: Jason | BJ7: Bright | BK7: Jason | BL7: Bright | BM7: Jason | BN7: Bright | BO7: Michael | BP7: Caruso | BQ7: Dean | BR7: Canto | BS7: Michael | BT7: Caruso | BU7: Dean | BV7: Canto | BW7: Michael | BX7: Caruso | BY7: Fabian | BZ7: Coulthard | CA7: Michael | CB7: Caruso | CC7: James | CD7: Courtney | CE7: James | CF7: Courtney | CG7: Fabian | CH7: Coulthard | CI7: Michael | CJ7: Caruso | CK7: Michael | CL7: Caruso | CM7: Matthew | CN7: Chahda | CO7: Aaron | CP7: Cameron
A8: John | B8: Calloway | C8: Bob | D8: Brown | E8: J. | F8: Binning | G8: Paul | H8: Bolton | I8: Warren | J8: Blomfield | K8: Bob | L8: Beasley | M8: Bob | N8: Beasley | O8: Bernie | P8: Breen | Q8: Damon | R8: Beck | S8: Kevin | T8: Bartlett | U8: Neal | V8: Bates | W8: Kevin | X8: Bartlett | Y8: Rick | Z8: Bates | AA8: Peter | AB8: Beck | AC8: Terry | AD8: Bosnjak | AE8: John | AF8: Blanchard | AG8: Brian | AH8: Callaghan | AI8: John | AJ8: Bowe | AK8: John | AL8: Bowe | AM8: Stephen | AN8: Bell | AO8: John | AP8: Bowe | AQ8: Gary | AR8: Baxter | AS8: John | AT8: Bowe | AU8: David | AV8: Besnard | AW8: John | AX8: Bowe | AY8: Dale | AZ8: Brede | BA8: Dale | BB8: Brede | BC8: Jason | BD8: Bright | BE8: James | BF8: Courtney | BG8: Fabian | BH8: Coulthard | BI8: Dean | BJ8: Canto | BK8: Ryan | BL8: Briscoe | BM8: Dean | BN8: Canto | BO8: Fabian | BP8: Coulthard | BQ8: Michael | BR8: Caruso | BS8: Fabian | BT8: Coulthard | BU8: Michael | BV8: Caruso | BW8: Fabian | BX8: Coulthard | BY8: James | BZ8: Courtney | CA8: Fabian | CB8: Coulthard | CC8: Tony | CD8: D'Alberto | CE8: Tony | CF8: D'Alberto | CG8: James | CH8: Courtney | CI8: Matthew | CJ8: Chahda | CK8: Fabian | CL8: Coulthard | CM8: Fabian | CN8: Coulthard | CO8: Fabian | CP8: Coulthard
A9: Peter | B9: Candy | C9: Lou | D9: Burke | E9: J. | F9: Bodinnar | G9: Jim | H9: Bonthorne | I9: Alton | J9: Boddenberg | K9: Alton | L9: Boddenberg | M9: Alton | N9: Boddenberg | O9: Mal | P9: Brewster | Q9: Alton | R9: Boddenberg | S9: Bryan | T9: Bate | U9: Frank | V9: Biela | W9: Neal | X9: Bates | Y9: Brian | Z9: Bolwell | AA9: Frank | AB9: Binding | AC9: John | AD9: Bowe | AE9: Colin | AF9: Bond | AG9: John | AH9: Cleland | AI9: Peter | AJ9: Brock | AK9: Peter | AL9: Bradbury | AM9: Domenic | AN9: Beninca | AO9: Geoff | AP9: Brabham | AQ9: Shane | AR9: Beikoff | AS9: Geoff | AT9: Brabham | AU9: John | AV9: Bowe | AW9: David | AX9: Brabham | AY9: Jason | AZ9: Bright | BA9: Jason | BB9: Bright | BC9: Ryan | BD9: Briscoe | BE9: Tony | BF9: D'Alberto | BG9: James | BH9: Courtney | BI9: Michael | BJ9: Caruso | BK9: Dean | BL9: Canto | BM9: Michael | BN9: Caruso | BO9: James | BP9: Courtney | BQ9: Fabian | BR9: Coulthard | BS9: James | BT9: Courtney | BU9: Fabian | BV9: Coulthard | BW9: James | BX9: Courtney | BY9: Tony | BZ9: D'Alberto | CA9: James | CB9: Courtney | CC9: Will | CD9: Davison | CE9: Alex | CF9: Davison | CG9: Tony | CH9: D'Alberto | CI9: Fabian | CJ9: Coulthard | CK9: James | CL9: Courtney | CM9: James | CN9: Courtney | CO9: James | CP9: Courtney
A10: Murray | B10: Carter | C10: Alan | D10: Caelli | E10: Peter | F10: Boyd-Squires | G10: Lex | H10: Brailey | I10: Paul | J10: Bolton | K10: Colin | L10: Bond | M10: Colin | N10: Bond | O10: Peter | P10: Brown | Q10: Chris | R10: Brauer | S10: Damon | T10: Beck | U10: Colin | V10: Bond | W10: Rick | X10: Bates | Y10: Colin | Z10: Bond | AA10: John | AB10: Blanchard | AC10: David | AD10: Brabham | AE10: John | AF10: Bowe | AG10: John | AH10: Cotter | AI10: Brian | AJ10: CallaghanJr | AK10: Kerryn | AL10: Brewer | AM10: John | AN10: Bowe | AO10: David | AP10: Brabham | AQ10: David | AR10: Besnard | AS10: Dale | AT10: Brede | AU10: Dale | AV10: Brede | AW10: Dale | AX10: Brede | AY10: Peter | AZ10: Brock | BA10: Dean | BB10: Canto | BC10: Dean | BD10: Canto | BE10: Alex | BF10: Davison | BG10: Tony | BH10: D'Alberto | BI10: Ben | BJ10: Collins | BK10: Michael | BL10: Caruso | BM10: Fabian | BN10: Coulthard | BO10: Tony | BP10: D'Alberto | BQ10: James | BR10: Courtney | BS10: Tony | BT10: D'Alberto | BU10: Tony | BV10: D'Alberto | BW10: Tony | BX10: D'Alberto | BY10: Will | BZ10: Davison | CA10: Tony | CB10: D'Alberto | CC10: Alex | CD10: Davison | CE10: Will | CF10: Davison | CG10: Will | CH10: Davison | CI10: James | CJ10: Courtney | CK10: Tony | CL10: D'Alberto | CM10: Cameron | CN10: Crick | CO10: Cameron | CP10: Crick
A11: Ray | B11: Christie | C11: Peter | D11: Candy | E11: John | F11: Brindley | G11: Ken | H11: Brigden | I11: Jim | J11: Bonthorne | K11: Midge | L11: Bosworth | M11: Peter | N11: Brown | O11: Lynn | P11: Brown | Q11: Mal | R11: Brewster | S11: Colin | T11: Bond | U11: John | V11: Bowe | W11: Russell | X11: Becker | Y11: John | Z11: Bowe | AA11: Brian | AB11: Bolwell | AC11: Geoff | AD11: Brabham | AE11: Peter | AF11: Brock | AG11: Greg | AH11: Crick | AI11: John | AJ11: Cleland | AK11: Tim | AL11: Briggs | AM11: Geoff | AN11: Brabham | AO11: John | AP11: Briggs | AQ11: John | AR11: Bowe | AS11: Jason | AT11: Bright | AU11: Jason | AV11: Bright | AW11: Jason | AX11: Bright | AY11: Dean | AZ11: Canto | BA11: John | BB11: Cleland | BC11: Michael | BD11: Caruso | BE11: Will | BF11: Davison | BG11: Will | BH11: Davison | BI11: Fabian | BJ11: Coulthard | BK11: Fabian | BL11: Coulthard | BM11: James | BN11: Courtney | BO11: Will | BP11: Davison | BQ11: Tony | BR11: D'Alberto | BS11: Robert | BT11: Dahlgren | BU11: Will | BV11: Davison | BW11: Shae | BX11: Davies | BY11: Alex | BZ11: Davison | CA11: Will | CB11: Davison | CC11: Anton | CD11: dePasquale | CE11: Anton | CF11: DePasquale | CG11: Alex | CH11: Davison | CI11: Tony | CJ11: D'Alberto | CK11: Will | CL11: Davison | CM11: Tony | CN11: D'Alberto | CO11: Tony | CP11: D'Alberto
A12: Bill | B12: Clemens | C12: Eddie | D12: Clay | E12: Bob | F12: Brown | G12: John | H12: Brindley | I12: Midge | J12: Bosworth | K12: Peter | L12: Brown | M12: Bill | N12: Buckle | O12: Bill | P12: Brown | Q12: Peter | R12: Brown | S12: John | T12: Bowe | U12: Gianfranco | V12: Brancatelli | W12: Frank | X12: Biela | Y12: Gary | Z12: Brabham | AA12: Colin | AB12: Bond | AC12: Peter | AD12: Brock | AE12: Kevin | AF12: Burton | AG12: Rodney | AH12: Crick | AI12: Mike | AJ12: Conway | AK12: Jason | AL12: Bright | AM12: Kerryn | AN12: Brewer | AO12: Jason | AP12: Bright | AQ12: Geoff | AR12: Brabham | AS12: James | AT12: Brock | AU12: Peter | AV12: Brock | AW12: Dean | AX12: Canto | AY12: John | AZ12: Cleland | BA12: Matthew | BB12: Coleman | BC12: Fabian | BD12: Coulthard | BE12: Grant | BF12: Denyer | BG12: Alex | BH12: Davison | BI12: James | BJ12: Courtney | BK12: James | BL12: Courtney | BM12: Tony | BN12: D'Alberto | BO12: Alex | BP12: Davison | BQ12: Will | BR12: Davison | BS12: Will | BT12: Davison | BU12: Alex | BV12: Davison | BW12: Will | BX12: Davison | BY12: Simona | BZ12: deSilvestro | CA12: Alex | CB12: Davison | CC12: Simona | CD12: deSilvestro | CE12: Tyler | CF12: Everingham | CG12: Anton | CH12: De Pasquale | CI12: Will | CJ12: Davison | CK12: Alex | CL12: Davison | CM12: Will | CN12: Davison | CO12: Lochie | CP12: Dalton
A13: Frank | B13: Coad | C13: Frank | D13: Coad | E13: Bill | F13: Buckle | G13: Barry | H13: Broomhall | I13: Peter | J13: Brown | K13: Bill | L13: Brown | M13: Bill | N13: Burns | O13: Bill | P13: Buckle | Q13: Bill | R13: Brown | S13: Peter | T13: Brock | U13: Peter | V13: Brock | W13: Brian | X13: Bolwell | Y13: Gianfranco | Z13: Brancatelli | AA13: Terry | AB13: Bosnjak | AC13: Brian | AD13: CallaghanJr | AE13: Brian | AF13: CallaghanJr | AG13: Neil | AH13: Crompton | AI13: John | AJ13: Cotter | AK13: Peter | AL13: Brock | AM13: Tim | AN13: Briggs | AO13: Dean | AP13: Canto | AQ13: Jason | AR13: Bright | AS13: Dean | AT13: Canto | AU13: Dean | AV13: Canto | AW13: John | AX13: Cleland | AY13: Fabian | AZ13: Coulthard | BA13: Fabian | BB13: Coulthard | BC13: James | BD13: Courtney | BE13: Paul | BF13: Dumbrell | BG13: Paul | BH13: Dumbrell | BI13: Tony | BJ13: D'Alberto | BK13: Tony | BL13: D'Alberto | BM13: Alex | BN13: Davison | BO13: Jesse | BP13: Dixon | BQ13: Alex | BR13: Davison | BS13: Alex | BT13: Davison | BU13: Simona | BV13: deSilvestro | BW13: Simona | BX13: deSilvestro | BY13: Taz | BZ13: Douglas | CA13: Anton | CB13: dePasquale | CC13: Dean | CD13: Fiore | CE13: Broc | CF13: Feeney | CG13: Broc | CH13: Feeney | CI13: Alex | CJ13: Davison | CK13: Anton | CL13: de Pasquale | CM13: Anton | CN13: De Pasquale | CO13: Will | CP13: Davison
... A49: Peter | B49: Manton | C49: John | D49: Raeburn | E49: Kingsley | F49: Hibbard | G49: Tony | H49: Hill | I49: Lorraine | J49: Hill | K49: Bruce | L49: Hodgson | M49: Paddy | N49: Hopkirk | O49: Clyde | P49: Hodgins | Q49: Paul | R49: Hawkins | S49: Geoff | T49: Leeds | U49: Denny | V49: Hulme | W49: Gregg | X49: Hansford | Y49: Alan | Z49: Jones | AA49: Bob | AB49: Holden | AC49: Alan | AD49: Jones | AE49: Tony | AF49: Longhurst | AG49: Win | AH49: Percy | AI49: David | AJ49: Parsons | AK49: Greg | AL49: Murphy | AM49: Andrew | AN49: Lloyd | AO49: Brad | AP49: Jones | AQ49: Owen | AR49: Kelly | AS49: Paul | AT49: Morris | AU49: Greg | AV49: Murphy | AW49: Larry | AX49: Perkins | AY49: Mark | AZ49: Porter | BA49: Nathan | BB49: Pretty | BC49: Steven | BD49: Richards | BE49: Luke | BF49: Youlden | BG49: Mark | BH49: Skaife | BI49: Greg | BJ49: Ritter | BK49: David | BL49: Russell | BM49: Tim | BN49: Slade | BO49: Tim | BP49: Slade | BQ49: Tim | BR49: Slade | BS49: Jonathon | BT49: Webb | BU49: Ashley | BV49: Walsh | BW49: Ashley | BX49: Walsh | BY49: Jonathon | BZ49: Webb | CA49: Jonathon | CB49: Webb | CC49: Jonathon | CD49: Webb | CE49: Jamie | CF49: Whincup | CG49: Mark | CH49: Winterbottom | CI49: Tim | CJ49: Slade | CK49: Jack | CL49: Smith | CM49: Cameron | CN49: Waters | CO49: Garth | CP49: Tander
A50: Bill | B50: March | C50: George | D50: Reynolds | E50: G. | F50: Hibberd | G50: Lorraine | H50: Hill | I50: Joe | J50: Hills | K50: Bob | L50: Holden | M50: Don | N50: James | O50: Bob | P50: Holden | Q50: Ron | R50: Haylen | S50: John | T50: Leeson | U50: Roger | V50: Hurd | W50: Bob | X50: Holden | Y50: Warren | Z50: Jonsson | AA50: Peter | AB50: Hopwood | AC50: Warren | AD50: Jonsson | AE50: Ian | AF50: Love | AG50: Larry | AH50: Perkins | AI50: Larry | AJ50: Perkins | AK50: Mark | AL50: Noske | AM50: Tony | AN50: Longhurst | AO50: Todd | AP50: Kelly | AQ50: Mark | AR50: Larkham | AS50: Kevin | AT50: Mundy | AU50: Mark | AV50: Noske | AW50: Mark | AX50: Porter | AY50: Nathan | AZ50: Pretty | BA50: Paul | BB50: Radisich | BC50: Jason | BD50: Richards | BG50: Garth | BH50: Tander | BI50: David | BJ50: Sieders | BK50: Glenn | BL50: Seton | BM50: Garth | BN50: Tander | BO50: Garth | BP50: Tander | BQ50: Garth | BR50: Tander | BS50: Jamie | BT50: Whincup | BU50: Cameron | BV50: Waters | BW50: Cameron | BX50: Waters | BY50: Jamie | BZ50: Whincup | CA50: Jamie | CB50: Whincup | CC50: Jamie | CD50: Whincup | CE50: Mark | CF50: Winterbottom | CG50: Dale | CH50: Wood | CI50: Jack | CJ50: Smith | CK50: Richie | CL50: Stanaway | CM50: Jamie | CN50: Whincup | CO50: Brad | CP50: Vaughan
A51: Lionel | B51: Marsh | C51: John | D51: Roxburgh | E51: Graham | F51: Hoinville | G51: Ron | H51: Hodgson | I51: Ron | J51: Hodgson | K51: Don | L51: Holland | M51: Bill | N51: Jamieson | O51: Don | P51: Holland | Q51: Ian | R51: Haynes | S51: Ray | T51: Lintott | U51: Peter | V51: Janson | W51: Denny | X51: Hulme | Y51: Graham | Z51: Jonsson | AA51: Denny | AB51: Hulme | AC51: Kurt | AD51: Kratzmann | AE51: Craig | AF51: Lowndes | AG51: Brett | AH51: Peters | AI51: Brett | AJ51: Peters | AK51: Bill | AL51: O'Brien | AM51: Craig | AN51: Lowndes | AO51: Geoff | AP51: Kendrick | AQ51: Tim | AR51: Leahey | AS51: Greg | AT51: Murphy | AU51: Steve | AV51: Owen | AW51: Nathan | AX51: Pretty | AY51: Paul | AZ51: Radisich | BA51: Jason | BB51: Richards | BC51: Jim | BD51: Richards | BG51: Andrew | BH51: Thompson | BI51: Allan | BJ51: Simonsen | BK51: Allan | BL51: Simonsen | BM51: Andrew | BN51: Thompson | BO51: Andrew | BP51: Thompson | BQ51: Andrew | BR51: Thompson | BS51: Mark | BT51: Winterbottom | BU51: Jonathon | BV51: Webb | BW51: Jonathon | BX51: Webb | BY51: Mark | BZ51: Winterbottom | CA51: Mark | CB51: Winterbottom | CC51: Mark | CD51: Winterbottom | CE51: Dale | CF51: Wood | CG51: Luke | CH51: Youlden | CI51: Richie | CJ51: Stanaway | CK51: Garth | CL51: Tander | CM51: Mark | CN51: Winterbottom | CO51: Cameron | CP51: Waters
A52: Jack | B52: Maurer | C52: Geoff | D52: Russell | E52: D. | F52: Hooker | G52: Bob | H52: Holden | I52: Bob | J52: Holden | K52: Pat | L52: Holmes | M52: Ron | N52: Kearns | O52: Paddy | P52: Hopkirk | Q52: Bruce | R52: Hindhaugh | S52: Tony | T52: Longhurst | U52: Dick | V52: Johnson | W52: Russell | X52: Ingall | Y52: Chris | Z52: Lambden | AA52: Peter | AB52: Janson | AC52: Tony | AD52: Longhurst | AE52: Matthew | AF52: Martin | AG52: Mark | AH52: Poole | AI52: Mark | AJ52: Poole | AK52: Charlie | AL52: O'Brien | AM52: Adam | AN52: Macrow | AO52: Mark | AP52: Larkham | AQ52: Dean | AR52: Lindstrom | AS52: Rod | AT52: Nash | AU52: Larry | AV52: Perkins | AW52: Andy | AX52: Priaulx | AY52: Jason | AZ52: Richards | BA52: Steven | BB52: Richards | BC52: Greg | BD52: Ritter | BG52: Shane | BH52: vanGisbergen | BI52: Mark | BJ52: Skaife | BK52: Mark | BL52: Skaife | BM52: Shane | BN52: vanGisbergen | BO52: Shane | BP52: vanGisbergen | BQ52: Shane | BR52: vanGisbergen | BS52: Dale | BT52: Wood | BU52: Jamie | BV52: Whincup | BW52: Jamie | BX52: Whincup | BY52: Dale | BZ52: Wood | CA52: Dale | CB52: Wood | CC52: Dale | CD52: Wood | CI52: Garth | CJ52: Tander | CK52: Shane | CL52: Van Gisbergen | CM52: Ryan | CN52: Wood | CO52: Jamie | CP52: Whincup
A53: David | B53: McKay | C53: Brian | D53: Sampson | E53: J. | F53: Hume | G53: Don | H53: Holland | I53: Don | J53: Holland | K53: Paddy | L53: Hopkirk | M53: Des | N53: Kelly | O53: Bob | P53: Jane | Q53: Gary | R53: Hodge | S53: Graham | T53: Lusty | U53: Alan | V53: Jones | W53: Peter | X53: Janson | Y53: Geoff | Z53: Leeds | AA53: Dick | AB53: Johnson | AC53: Graham | AD53: Lusty | AE53: Ken | AF53: Mathews | AG53: Steve | AH53: Reed | AI53: Miles | AJ53: Pope | AK53: Danny | AL53: Osborne | AM53: Allan | AN53: McCarthy | AO53: Tim | AP53: Leahey | AQ53: Tony | AR53: Longhurst | AS53: Mark | AT53: Noske | AU53: Mark | AV53: Porter | AW53: Paul | AX53: Radisich | AY53: Steven | AZ53: Richards | BA53: Jim | BB53: Richards | BC53: Kayne | BD53: Scott | BG53: Jonathon | BH53: Webb | BI53: Tim | BJ53: Slade | BK53: Tim | BL53: Slade | BM53: David | BN53: Wall | BO53: David | BP53: Wall | BQ53: David | BR53: Wall | BS53: Luke | BT53: Youlden | BU53: Mark | BV53: Winterbottom | BW53: Mark | BX53: Winterbottom | BY53: Luke | BZ53: Youlden | CA53: Luke | CB53: Youlden | CC53: Luke | CD53: Youlden | CI53: Shane | CJ53: Van Gisbergen | CK53: Cameron | CL53: Waters | CM53: Dale | CN53: Wood | CO53: Mark | CP53: Winterbottom
A54: Max | B54: McPherson | C54: Jacques | D54: Sapir | E54: A. | F54: Humphries | G54: Sid | H54: Howard | I54: Phil | J54: Ismay | K54: Bob | L54: Jane | M54: Carl | N54: Kennedy | O54: Mike | P54: Kable | Q54: Clyde | R54: Hodgins | S54: John | T54: Lusty | U54: Brad | V54: Jones | W54: Dick | X54: Johnson | Y54: Ray | Z54: Lintott | AA54: Bob | AB54: Jones | AC54: John | AD54: Lusty | AE54: Stuart | AF54: McColl | AG54: Steven | AH54: Richards | AI54: Steve | AJ54: Reed | AK54: Ian | AL54: Palmer | AM54: Cameron | AN54: McConville | AO54: Dean | AP54: Lindstrom | AQ54: Craig | AR54: Lowndes | AS54: Steve | AT54: Owen | AU54: Will | AV54: Power | AW54: Jonny | AX54: Reid | AY54: Jim | AZ54: Richards | BA54: Greg | BB54: Ritter | BC54: Glenn | BD54: Seton | BG54: Paul | BH54: Weel | BI54: Garth | BJ54: Tander | BK54: Garth | BL54: Tander | BM54: Cameron | BN54: Waters | BO54: Cameron | BP54: Waters | BQ54: Ashley | BR54: Walsh | BU54: Dale | BV54: Wood | BW54: Dale | BX54: Wood | CI54: Cameron | CJ54: Waters | CK54: Jonathon | CL54: Webb | CO54: Ryan | CP54: Wood
A55: Austin | B55: Miller | C55: Charlie | D55: Smith | E55: Jack | F55: Hunnam | G55: Les | H55: Howard | I55: Bob | J55: Jane | K55: Don | L55: Johnston | M55: Moto | N55: Kitano | O55: Carl | P55: Kennedy | Q55: Don | R55: Holland | S55: Andrew | T55: Maher | U55: Gerald | V55: Kay | W55: Bob | X55: Jones | Y55: Tony | Z55: Longhurst | AA55: Brad | AB55: Jones | AC55: Chris | AD55: Madden | AE55: Cameron | AF55: McConville | AG55: Jim | AH55: Richards | AI55: Steven | AJ55: Richards | AK55: David | AL55: Parsons | AM55: Mark | AN55: McLaughlin | AO55: Tony | AP55: Longhurst | AQ55: Adam | AR55: Macrow | AS55: David | AT55: Parsons | AU55: Nathan | AV55: Pretty | AW55: Tony | AX55: Ricciardello | AY55: Greg | AZ55: Ritter | BA55: Phillip | BB55: Scifleet | BC55: Allan | BD55: Simonsen | BG55: Jamie | BH55: Whincup | BI55: Leanne | BJ55: Tander | BK55: Andrew | BL55: Thompson | BM55: Jonathon | BN55: Webb | BO55: Jonathon | BP55: Webb | BQ55: Jonathon | BR55: Webb | BU55: Luke | BV55: Youlden | BW55: Luke | BX55: Youlden | CI55: Jamie | CJ55: Whincup | CK55: Jamie | CL55: Whincup | CO55: Dale | CP55: Wood
A56: Clyde | B56: Miller | C56: Ian | D56: Strachan | E56: George | F56: Huse | G56: Dave | H56: Humphries | I56: Don | J56: Johnston | K56: Ray | L56: Kaleda | M56: Brian | N56: Lawler | O56: John | P56: Leffler | Q56: Don | R56: James | S56: Steve | T56: Masterton | U56: Mike | V56: King | W56: Alan | X56: Jones | Y56: Graham | Z56: Lusty | AA56: Rodney | AB56: Jones | AC56: Matthew | AD56: Martin | AE56: Peter | AF56: McKay | AG56: Paul | AH56: Romano | AI56: Jim | AJ56: Richards | AK56: Darren | AL56: Pate | AM56: Cameron | AN56: McLean | AO56: Craig | AP56: Lowndes | AQ56: Cameron | AR56: McConville | AS56: Larry | AT56: Perkins | AU56: Andy | AV56: Priaulx | AW56: Steven | AX56: Richards | AY56: Glenn | AZ56: Seton | BA56: Kayne | BB56: Scott | BC56: Mark | BD56: Skaife | BG56: Max | BH56: Wilson | BI56: Andrew | BJ56: Thompson | BK56: Shane | BL56: vanGisbergen | BM56: Jamie | BN56: Whincup | BO56: Jamie | BP56: Whincup | BQ56: Jamie | BR56: Whincup | CI56: Mark | CJ56: Winterbottom | CK56: Mark | CL56: Winterbottom
A57: Lou | B57: Molina | C57: Fred | D57: Sutherland | E57: Mike | F57: Ide | G57: Bob | H57: Jane | I57: Ray | J57: Kaleda | K57: Tony | L57: Kavanagh | M57: Alex | N57: Lazich | O57: Gerry | P57: Lister | Q57: Allan | R57: Johns | S57: Ken | T57: Mathews | U57: Chris | V57: Lambden | W57: Brad | X57: Jones | Y57: Glenn | Z57: McIntyre | AA57: Alan | AB57: Jones | AC57: Spencer | AD57: Martin | AE57: Ryan | AF57: McLeod | AG57: Warwick | AH57: Rooklyn | AI57: Paul | AJ57: Romano | AK57: Bob | AL57: Pearson | AM57: Alain | AN57: Menu | AO57: Adam | AP57: Macrow | AQ57: Dugal | AR57: McDougall | AS57: Nathan | AT57: Pretty | AU57: Paul | AV57: Radisich | AW57: Jim | AX57: Richards | AY57: Allan | AZ57: Simonsen | BA57: Glenn | BB57: Seton | BC57: Garth | BD57: Tander | BG57: Mark | BH57: Winterbottom | BI57: James | BJ57: Thompson | BK57: David | BL57: Wall | BM57: Mark | BN57: Winterbottom | BO57: Mark | BP57: Winterbottom | BQ57: Mark | BR57: Winterbottom | CI57: Dale | CJ57: Wood | CK57: Dale | CL57: Wood
A58: Brian | B58: Muir | C58: Ian | D58: Trudinger | E58: Bob | F58: Jane | G58: Doug | H58: Kelley | I58: Eric | J58: Lane | K58: Des | L58: Kelly | M58: Geoff | N58: Leeds | O58: Lindsay | P58: Little | Q58: Ernie | R58: Johnson | S58: Peter | T58: McKay | U58: Geoff | V58: Leeds | W58: Garry | X58: Jones | Y58: Tomas | Z58: Mezera | AA58: Garry | AB58: Jones | AC58: Glenn | AD58: Mason | AE58: Peter | AF58: McLeod | AG58: Wayne | AH58: Russell | AI58: Mal | AJ58: Rose | AK58: Win | AL58: Percy | AM58: Tomas | AN58: Mezera | AO58: Cameron | AP58: McConville | AQ58: Aaron | AR58: McGill | AS58: Paul | AT58: Radisich | AU58: Jason | AV58: Richards | AW58: Jason | AX58: Richards | AY58: Mark | AZ58: Skaife | BA58: Allan | BB58: Simonsen | BC58: Anthony | BD58: Tratt | BG58: Dale | BH58: Wood | BI58: Shane | BJ58: vanGisbergen | BK58: Jonathon | BL58: Webb | BM58: Dale | BN58: Wood | BO58: Dale | BP58: Wood | BQ58: Dale | BR58: Wood
A59: W. | B59: Murison | C59: Joe | D59: Vanaria | E59: Diane | F59: Leighton | G59: Graham | H59: Kelley | I59: Brian | J59: Lawler | K59: Carl | L59: Kennedy | M59: John | N59: Leffler | O59: Doug | P59: Macarthur | Q59: Mike | R59: Kable | S59: Peter | T59: McLeod | U59: John | V59: Leeson | W59: Graham | X59: Jonsson | Y59: Andrew | Z59: Miedecke | AA59: Warren | AB59: Jonsson | AC59: Steve | AD59: Masterton | AE59: Tomas | AF59: Mezera | AG59: Neil | AH59: Schembri | AI59: Wayne | AJ59: Russell | AK59: Larry | AL59: Perkins | AM59: Richard | AN59: Mork | AO59: Dugal | AP59: McDougall | AQ59: Cameron | AR59: McLean | AS59: Steve | AT59: Reed | AU59: Jim | AV59: Richards | AW59: Greg | AX59: Ritter | AY59: Paul | AZ59: Stokell | BA59: Mark | BB59: Skaife | BC59: Jonathon | BD59: Webb | BG59: Luke | BH59: Youlden | BI59: David | BJ59: Wall | BK59: Jamie | BL59: Whincup | BM59: Luke | BN59: Youlden | BO59: Luke | BP59: Youlden | BQ59: Luke | BR59: Youlden
A60: Rod | B60: Murphy | C60: M | D60: Watson | E60: Kevin | F60: Lott | G60: Carl | H60: Kennedy | I60: Bruce | J60: Maher | K60: Brian | L60: Lawler | M60: Ken | N60: Lindsay | O60: Alex | P60: Macarthur | Q60: Ron | R60: Kearns | S60: Tomas | T60: Mezera | U60: Ray | V60: Lintott | W60: Chris | X60: Lambden | Y60: Steve | Z60: Millen | AA60: Robbie | AB60: Ker | AC60: Ken | AD60: Mathews | AE60: Andrew | AF60: Miedecke | AG60: Tony | AH60: Scott | AI60: Tony | AJ60: Scott | AK60: Mark | AL60: Poole | AM60: Greg | AN60: Murphy | AO60: Cameron | AP60: McLean | AQ60: Ryan | AR60: McLeod | AS60: Tony | AT60: Ricciardello | AU60: Steven | AV60: Richards | AW60: Mal | AX60: Rose | AY60: Garth | AZ60: Tander | BA60: Alex | BB60: Tagliani | BC60: Paul | BD60: Weel | BI60: Sam | BJ60: Walter | BK60: Mark | BL60: Winterbottom
A61: Jack | B61: Murray | C61: Jim | D61: White | E61: Reg | F61: Lunn | G61: Frank | H61: Kleinig | I61: Paul | J61: Mander | K61: Ken | L61: Lindsay | M61: Gerry | N61: Lister | O61: Glen | P61: Mackinnon | Q61: Carl | R61: Kennedy | S61: Andrew | T61: Miedecke | U61: Tony | V61: Longhurst | W61: Geoff | X61: Leeds | Y61: Graham | Z61: Moore | AA61: Ed | AB61: Lamont | AC61: John | AD61: Mathews | AE61: Jamie | AF61: Miller | AG61: Glenn | AH61: Seton | AI61: Glenn | AJ61: Seton | AK61: Melinda | AL61: Price | AM61: Rod | AN61: Nash | AO61: Tomas | AP61: Mezera | AQ61: Tyler | AR61: Mecklem | AS61: Jim | AT61: Richards | AU61: Greg | AV61: Ritter | AW61: David | AX61: Russell | AY61: Anthony | AZ61: Tratt | BA61: Garth | BB61: Tander | BC61: Jamie | BD61: Whincup | BI61: Jonathon | BJ61: Webb | BK61: Dale | BL61: Wood
A62: Bill | B62: Murray | C62: Doug | D62: Whiteford | E62: Peter | F62: Macrow | G62: Terry | H62: Kratzmann | I62: Bill | J62: March | K62: Lindsay | L62: Little | M62: Alex | N62: Macarthur | O62: Peter | P62: Macrow | Q62: James | R62: Laing-Peach | S62: Allan | T62: Moffat | U62: Graham | V62: Lorimer | W62: Ray | X62: Lintott | Y62: Geoff | Z62: Morgan | AA62: Tony | AB62: Longhurst | AC62: Stuart | AD62: McColl | AE62: Paul | AF62: Morris | AG62: Richard | AH62: Shaw | AI62: Rick | AJ62: Shaw | AK62: Scott | AL62: Pruett | AM62: Mark | AN62: Noske | AO62: Andrew | AP62: Miedecke | AQ62: Alain | AR62: Menu | AS62: Jason | AT62: Richards | AU62: Phillip | AV62: Scifleet | AW62: Rickard | AX62: Rydell | AY62: Garth | AZ62: Walden | BA62: Anthony | BB62: Tratt | BC62: Max | BD62: Wilson | BI62: Jamie | BJ62: Whincup | BK62: Luke | BL62: Youlden
A63: Bill | B63: Nalder | C63: Peter | D63: Will[5] | E63: Jack | F63: Madden | G63: Brian | H63: Lawler | I63: John | J63: Marchiori | K63: Bruce | L63: Maher | M63: Paul | N63: Mander | O63: Timo | P63: Mäkinen | Q63: Gary | R63: Leggatt | S63: Graham | T63: Moore | U63: Graham | V63: Lusty | W63: Tony | X63: Longhurst | Y63: Paul | Z63: Morris | AA63: Ken | AB63: Mathews | AC63: Cameron | AD63: McConville | AE63: Greg | AF63: Murphy | AG63: Mark | AH63: Skaife | AI63: Terry | AJ63: Shiel | AK63: Trevor | AL63: Reed | AM63: Danny | AN63: Osborne | AO63: Daniel | AP63: Miller | AQ63: Tomas | AR63: Mezera | AS63: Steven | AT63: Richards | AU63: Tony | AV63: Scott | AW63: Phillip | AX63: Scifleet | AY63: Paul | AZ63: Weel | BA63: Paul | BB63: Weel | BC63: Mark | BD63: Winterbottom | BI63: Mark | BJ63: Winterbottom | BK63: Marcus | BL63: Zukanovic
A64: Jack | B64: Nougher | E64: Bruce | F64: Maher | G64: Lindsay | H64: Little | I64: Spencer | J64: Martin | K64: Timo | L64: Mäkinen | M64: Ray | N64: Marquet | O64: Paul | P64: Mander | Q64: Ron | R64: Marks | S64: Michael | T64: Mortimer | U64: John | V64: Mann | W64: Graham | X64: Lusty | Y64: Charlie | Z64: O'Brien | AA64: Stuart | AB64: McColl | AC64: David | AD64: McMillan | AE64: Troy | AF64: Nicholson | AG64: Bernie | AH64: Stack | AI64: Bill | AJ64: Sieders | AK64: Steven | AL64: Richards | AM64: Ian | AN64: Palmer | AO64: Richard | AP64: Mork | AQ64: Andrew | AR64: Miedecke | AS64: Greg | AT64: Ritter | AU64: Ron | AV64: Searle | AW64: Ron | AX64: Searle | AY64: Jamie | AZ64: Whincup | BA64: Jamie | BB64: Whincup | BC64: Luke | BD64: Youlden | BI64: Dale | BJ64: Wood
A65: Ken (Rex) | B65: Orman | E65: Lionel | F65: Marsh | G65: Greg | H65: Mackie | I65: Mike | J65: Martin | K65: Paul | L65: Mander | M65: Lew | N65: Marshall | O65: Lakis | P65: Manticas | Q65: Ray | R65: Marquet | S65: Tony | T65: Mulvihill | U65: Ken | V65: Mathews | W65: John | X65: Lusty | Y65: Bill | Z65: O'Brien | AA65: Tomas | AB65: Mezera | AC65: Gregg | AD65: McShane | AE65: Charlie | AF65: O'Brien | AG65: Bruce | AH65: Stewart | AI65: Mark | AJ65: Skaife | AK65: Jim | AL65: Richards | AM65: David | AN65: Parsons | AO65: Paul | AP65: Morris | AQ65: Ian | AR65: Moncrieff | AS65: Paul | AT65: Romano | AU65: Glenn | AV65: Seton | AW65: Glenn | AX65: Seton | AY65: Matthew | AZ65: White | BA65: Damien | BB65: White | BI65: Luke | BJ65: Youlden
A66: Les | B66: Park | E66: Stan | F66: Martin | G66: Peter | H66: Manton | I66: Brian | J66: McGrath | K66: Peter | L66: Manton | M66: Mike | N66: Martin | O66: Spencer | P66: Martin | Q66: Spencer | R66: Martin | S66: Geoff | T66: Munday | U66: Joe | V66: McAndrew | W66: Andrew | X66: McDowell | Y66: Rohan | Z66: Onslow | AA66: Andrew | AB66: Miedecke | AC66: Tomas | AD66: Mezera | AE66: Anders | AF66: Olofsson | AG66: Scotty | AH66: Taylor | AI66: Chris | AJ66: Smerdon | AK66: Paul | AL66: Romano | AM66: David | AN66: Parsons | AO66: Greg | AP66: Murphy | AQ66: Richard | AR66: Mork | AS66: Rod | AT66: Salmon | AU66: Micheal | AV66: Simpson | AW66: Allan | AX66: Simonsen | AY66: Simon | AZ66: Wills | BA66: Matthew | BB66: White
A67: Eddie | B67: Perkins | E67: Frank | F67: McEnroe | G67: Bill | H67: March | I67: Neil | J67: McKay | K67: John | L67: Marchiori | M67: Frank | N67: Matich | O67: Bruce | P67: McIntyre | Q67: Trevor | R67: Mason | S67: Akihiko | T67: Nakaya | U67: Glenn | V67: McIntyre | W67: Glenn | X67: McIntyre | Y67: Wayne | Z67: Park | AA67: Graham | AB67: Moore | AC67: Andrew | AD67: Miedecke | AE67: Ian | AF67: Palmer | AG67: Stephen | AH67: Voight | AI67: Scotty | AJ67: Taylor | AK67: Mal | AL67: Rose | AM67: Darren | AN67: Pate | AO67: Rod | AP67: Nash | AQ67: Paul | AR67: Morris | AS67: Phillip | AT67: Scifleet | AU67: Mark | AV67: Skaife | AW67: Mark | AX67: Skaife | AY67: Max | AZ67: Wilson | BA67: Max | BB67: Wilson
A68: G. | B68: Petty | E68: Jim | F68: McKeown | G68: John | H68: Marchiori | I68: C. | J68: McLean | K68: Spencer | L68: Martin | M68: Bruce | N68: McPhee | O68: David | P68: McKay | Q68: Neil | R68: Mason | S68: Klaus | T68: Niedzwiedz | U68: Peter | V68: McKay | W68: Peter | X68: McKay | Y68: David | Z68: Parsons | AA68: Paul | AB68: Morris | AC68: Gavin | AD68: Monaghan | AE68: David | AF68: Parsons | AG68: Kevin | AH68: Waldock | AI68: John | AJ68: Trimbole | AK68: Wayne | AL68: Russell | AM68: Larry | AN68: Perkins | AO68: Mark | AP68: Noske | AQ68: Yvan | AR68: Muller | AS68: Glenn | AT68: Seton | AU68: Paul | AV68: Stokell | AW68: Paul | AX68: Stokell | AY68: Kurt | AZ68: Wimmer | BA68: Mark | BB68: Winterbottom
A69: Ron | B69: Phillips | E69: Lou | F69: Molina | G69: Trevor | H69: Marden | I69: Lyndon | J69: McLeod | K69: Brian | L69: McGrath | M69: Trevor | N69: Meehan | O69: Trevor | P69: Meehan | Q69: Bruce | R69: McIntyre | S69: Tony | T69: Noske | U69: Warren | V69: McKellar | W69: Mark | X69: McLaughlin | Y69: Bob | Z69: Pearson | AA69: Stuart | AB69: Murphy | AC69: Paul | AD69: Morris | AE69: Win | AF69: Percy | AI69: Kevin | AJ69: Waldock | AK69: Neil | AL69: Schembri | AM69: Brett | AN69: Peters | AO69: Danny | AP69: Osborne | AQ69: Christian | AR69: Murchison | AS69: Micheal | AT69: Simpson | AU69: Garth | AV69: Tander | AW69: Garth | AX69: Tander | AY69: Mark | AZ69: Winterbottom | BA69: Luke | BB69: Youlden
A70: Bill | B70: Pitt | E70: Pam | F70: Murison | G70: Ron | H70: Marshall | I70: Bruce | J70: McPhee | K70: Neil | L70: McKay | M70: Ray | N70: Morris | O70: John | P70: Millyard | Q70: Jim | R70: McKeown | S70: Bill | T70: O'Brien | U70: Tomas | V70: Mezera | W70: Tomas | X70: Mezera | Y70: Win | Z70: Percy | AA70: Nick | AB70: Newton | AC70: Tony | AD70: Mulvihill | AE70: Larry | AF70: Perkins | AI70: Gary | AJ70: Waldon | AK70: Tony | AL70: Scott | AM70: Mark | AN70: Poole | AO70: Steve | AP70: Owen | AQ70: Greg | AR70: Murphy | AS70: Mark | AT70: Skaife | AU70: Anthony | AV70: Tratt | AW70: David | AX70: Thexton | AY70: Alex | AZ70: Yoong
A71: Brian | B71: Pyers | E71: W. | F71: Murison | G71: John | H71: Martin | I71: Chris | J71: McSorley | K71: Bill | L71: McLachlan | M71: Allan | N71: Mottram | O71: Allan | P71: Mottram | Q71: Bruce | R71: McPhee | S71: Mike | T71: Oliver | U71: Andrew | V71: Miedecke | W71: Andrew | X71: Miedecke | Y71: Larry | Z71: Perkins | AA71: Klaus | AB71: Niedzwiedz | AC71: Bill | AD71: O'Brien | AE71: Brett | AF71: Peters | AI71: Kevin | AJ71: Weeks | AK71: Bill | AL71: Seiders | AM71: Nathan | AN71: Pretty | AO71: David | AP71: Parsons | AQ71: Rod | AR71: Nash | AS71: Ashley | AT71: Stichbury | AU71: Wayne | AV71: Wakefield | AW71: Anthony | AX71: Tratt | AY71: Luke | AZ71: Youlden
A72: John | B72: Reaburn | E72: Wes | F72: Nalder | G72: Spencer | H72: Martin | I72: Brian | J72: Milton | K72: Bruce | L72: McPhee | M72: Barry | N72: Mulholland | O72: George | P72: Murray | Q72: Mel | R72: Mollison | S72: Anders | T72: Olofsson | U72: Graham | V72: Moore | W72: Graham | X72: Moore | Y72: Brett | Z72: Peters | AA72: Bill | AB72: O'Brien | AC72: Charlie | AD72: O'Brien | AE72: Michael | AF72: Preston | AI72: Garry | AJ72: Willmington | AK72: Glenn | AL72: Seton | AM72: Melinda | AN72: Price | AO72: David | AP72: Parsons | AQ72: Matt | AR72: Neal | AS72: Garth | AT72: Tander | AU72: Paul | AV72: Weel | AW72: Stephen | AX72: Voight
A73: George | B73: Reynolds | E73: Les | F73: Park | G73: Mike | H73: Martin | I73: Peter | J73: Mitchell[6] | K73: Trevor | L73: Meehan | M73: Jack | N73: Murray | O73: Jack | P73: Murray | Q73: Bob | R73: Morris | S73: Wayne | T73: Park | U73: Tony | V73: Mulvihill | W73: Tony | X73: Mulvihill | Y73: Drew | Z73: Price | AA73: Charlie | AB73: O'Brien | AC73: Anders | AD73: Olofsson | AE73: Melinda | AF73: Price | AK73: Rick | AL73: Shaw | AM73: Gary | AN73: Quartly | AO73: Darren | AP73: Pate | AQ73: Steve | AR73: Owen | AS73: Anthony | AT73: Tratt | AU73: Jamie | AV73: Whincup | AW73: Kerry | AX73: Wade
A74: John | B74: Roxburgh | E74: Frank | F74: Porter | G74: Frank | H74: Matich | I74: Allan | J74: Mottram | K74: Graham | L74: Moore | M74: Jack | N74: Nougher | O74: Kevin | P74: Nipperess | Q74: Ray | R74: Morris | S74: David | T74: Parsons | U74: Klaus | V74: Niedzwiedz | W74: Klaus | X74: Niedzwiedz | Y74: Paul | Z74: Radisich | AA74: Anders | AB74: Olofsson | AC74: David | AD74: Parsons | AE74: Paul | AF74: Radisich | AK74: Terry | AL74: Shiel | AM74: Steve | AN74: Reed | AO74: Larry | AP74: Perkins | AQ74: David'T' | AR74: Parsons | AS74: Wayne | AT74: Wakefield | AU74: Mathew | AV74: White | AW74: Wayne | AX74: Wakefield
A75: Geoff | B75: Russell | E75: George | F75: Poulton | G75: Phil | H75: McCumisky | I75: Brian | J75: Muir | K75: Ray | L75: Morris | M75: David | N75: O'Keefe | O75: Jack | P75: Nougher | Q75: Brian | R75: Muir | S75: Win | T75: Percy | U75: Tony | V75: Noske | W75: Bill | X75: O'Brien | Y75: Steve | Z75: Reed | AA75: Rohan | AB75: Onslow | AC75: Darren | AD75: Pate | AE75: Steve | AF75: Reed | AK75: Mark | AL75: Skaife | AM75: Steven | AN75: Richards | AO75: Brett | AP75: Peters | AQ75: David'S' | AR75: Parsons | AS75: Paul | AT75: Weel | AU75: Simon | AV75: Wills | AW75: Paul | AX75: Weel
...

Sheet Yearly Race Winners
A2: Year | B2: Event Name | D2: Driver(s) | F2: Driver(s) | H2: Driver(s) | J2: Car | O2: Race average speed
E3: Country | G3: Country | K3: Laps | M3: Elapsed time
A4: Phillip Island (500 Miles)
A5: 1960 | B5: Armstrong 500 | C5: 1 | D5: John Roxburgh | E5: AUS | F5: Frank Coad | G5: AUS | J5: Vauxhall Cresta | K5: 167 | M5: 8h 20m 45.0s | O5: 96.42 km/h | Q5: 59.91 mph
A6: 1961 | B6: Armstrong 500 | C6: 1 | D6: Bob Jane | E6: AUS | F6: Harry Firth | G6: AUS | J6: Mercedes-Benz 220SE | K6: 167 | M6: 8h 0m 31.0s | O6: 100.48 km/h | Q6: 62.43 mph
A7: 1962 | B7: Armstrong 500 | C7: 1 | D7: Harry Firth | E7: AUS | F7: Bob Jane | G7: AUS | J7: Ford XL Falcon | K7: 167 | M7: 8h 15m 16.0s | O7: 97.48 km/h | Q7: 60.57 mph
A8: Mount Panorama (500 Miles)
A9: 1963 | B9: Armstrong 500 | C9: 1 | D9: Harry Firth | E9: AUS | F9: Bob Jane | G9: AUS | J9: Ford Cortina Mk.I GT | K9: 130 | M9: 7h 47m 14.0s | O9: 103.33 km/h | Q9: 64.21 mph
A10: 1964 | B10: Armstrong 500 | C10: 1 | D10: Bob Jane | E10: AUS | F10: George Reynolds | G10: AUS | J10: Ford Cortina Mk.I GT | K10: 130 | M10: — | O10: — | Q10: —
A11: 1965 | B11: Armstrong 500 | D11: Barry Seton | E11: AUS | F11: Midge Bosworth | G11: AUS | J11: Ford Cortina Mk.I GT500 | K11: 130 | M11: 7h 16m 45.1s | O11: 110.54 km/h | Q11: 68.69 mph
A12: 1966 | B12: Gallaher 500 | D12: Rauno Aaltonen | E12: FIN | F12: Bob Holden | G12: AUS | J12: Morris Cooper S | K12: 130 | M12: 7h 11m 29.1s | O12: 111.89 km/h | Q12: 69.53 mph
A13: 1967 | B13: Gallaher 500 | D13: Harry Firth | E13: AUS | F13: Fred Gibson | G13: AUS | J13: Ford XR Falcon GT | K13: 130 | M13: 6h 55m 8.0s | O13: 116.30 km/h | Q13: 72.27 mph
A14: 1968 | B14: Hardie-Ferodo 500 | D14: Bruce McPhee | E14: AUS | F14: Barry Mulholland | G14: AUS | J14: Holden HK Monaro GTS327 | K14: 130 | M14: 6h 44m 7.0s | O14: 119.47 km/h | Q14: 74.24 mph
A15: 1969 | B15: Hardie-Ferodo 500 | D15: Colin Bond | E15: AUS | F15: Tony Roberts | G15: AUS | J15: Holden HT Monaro GTS350 | K15: 130 | M15: 6h 32m 25s | O15: 123.16 km/h | Q15: 76.53 mph
A16: 1970 | B16: Hardie-Ferodo 500 | D16: Allan Moffat | E16: CAN | J16: Ford XW Falcon GTHO Phase II | K16: 130 | M16: 6h 33m 47.0s | O16: 122.61 km/h | Q16: 76.18 mph
A17: 1971 | B17: Hardie-Ferodo 500 | D17: Allan Moffat | E17: CAN | J17: Ford XY Falcon GTHO Phase III | K17: 130 | M17: 6h 9m 49.5s | O17: 130.55 km/h | Q17: 81.12 mph
A18: 1972 | B18: Hardie-Ferodo 500 | D18: Peter Brock | E18: AUS | J18: Holden LJ Torana GTR XU-1 | K18: 130 | M18: 6h 1m 53.0s | O18: 133.41 km/h | Q18: 82.90 mph
A19: Mount Panorama (1,000 Kilometres)
A20: 1973 | B20: Hardie-Ferodo 1000 | D20: Allan Moffat | E20: CAN | F20: Ian Geoghegan | G20: AUS | J20: Ford XA Falcon GT Hardtop | K20: 163 | M20: 7h 20m 6.8s | O20: 136.33 km/h | Q20: 84.71 mph
A21: 1974 | B21: Hardie-Ferodo 1000 | D21: John Goss | E21: AUS | F21: Kevin Bartlett | G21: AUS | J21: Ford XA Falcon GT Hardtop | K21: 163 | M21: 7h 51m 43.0s | O21: 127.19 km/h | Q21: 79.04 mph
A22: 1975 | B22: Hardie-Ferodo 1000 | D22: Peter Brock | E22: AUS | F22: Brian Sampson | G22: AUS | J22: Holden LH Torana SL/R 5000 L34 | K22: 163 | M22: 7h 10m 11.3s | O22: 139.47 km/h | Q22: 86.66 mph
A23: 1976 | B23: Hardie-Ferodo 1000 | D23: Bob Morris | E23: AUS | F23: John Fitzpatrick | G23: GBR | J23: Holden LH Torana SL/R 5000 L34 | K23: 163 | M23: 7h 7m 12.0s | O23: 140.45 km/h | Q23: 87.27 mph
A24: 1977 | B24: Hardie-Ferodo 1000 | D24: Allan Moffat | E24: CAN | F24: Jacky Ickx | G24: BEL | J24: Ford XC Falcon GS500 Hardtop | K24: 163 | M24: 6h 59m 7.8s | O24: 143.15 km/h | Q24: 88.95 mph
A25: 1978 | B25: Hardie-Ferodo 1000 | D25: Peter Brock | E25: AUS | F25: Jim Richards | G25: NZL | J25: Holden LX Torana A9X SS Hatchback | K25: 163 | M25: 6h 45m 53.9s | O25: 147.82 km/h | Q25: 91.85 mph
A26: 1979 | B26: Hardie-Ferodo 1000 | D26: Peter Brock | E26: AUS | F26: Jim Richards | G26: NZL | J26: Holden LX Torana A9X SS Hatchback | K26: 163 | M26: 6h 38m 15.8s | O26: 150.65 km/h | Q26: 93.61 mph
A27: 1980 | B27: Hardie-Ferodo 1000 | D27: Peter Brock | E27: AUS | F27: Jim Richards | G27: NZL | J27: Holden VC Commodore | K27: 163 | M27: 6h 47m 52.7s | O27: 147.10 km/h | Q27: 91.41 mph
A28: 1981 | B28: James Hardie 1000 | D28: Dick Johnson | E28: AUS | F28: John French | G28: AUS | J28: Ford XD Falcon | K28: 120 | L28: 2 | M28: 4h 53m 52.7s | O28: 150.31 km/h | Q28: 93.40 mph
A29: 1982 | B29: James Hardie 1000 | D29: Peter Brock | E29: AUS | F29: Larry Perkins | G29: AUS | J29: Holden VH Commodore SS | K29: 163 | M29: 6h 32m 3.2s | O29: 153.04 km/h | Q29: 95.09 mph
A30: 1983 | B30: James Hardie 1000 | D30: Peter Brock | E30: AUS | F30: John Harvey | G30: AUS | H30: Larry Perkins | I30: AUS | J30: Holden VH Commodore SS | K30: 163 | M30: 6h 28m 31.6s | O30: 154.43 km/h | Q30: 95.96 mph
A31: 1984 | B31: James Hardie 1000 | D31: Peter Brock | E31: AUS | F31: Larry Perkins | G31: AUS | J31: Holden VK Commodore | K31: 163 | M31: 6h 23m 13.06s | O31: 156.57 km/h | Q31: 97.29 mph
A32: 1985 | B32: James Hardie 1000 | D32: John Goss | E32: AUS | F32: Armin Hahne | G32: DEU | J32: Jaguar XJ-S | K32: 163 | M32: 6h 41m 30.19s | O32: 149.44 km/h | Q32: 92.86 mph
A33: 1986 | B33: James Hardie 1000 | D33: Allan Grice | E33: AUS | F33: Graeme Bailey | G33: AUS | J33: Holden VK Commodore SS Group A | K33: 163 | M33: 6h 30m 35.68s | O33: 153.61 km/h | Q33: 95.45 mph
A34: 1987 | B34: James Hardie 1000 | D34: Peter Brock | E34: AUS | F34: David Parsons | G34: AUS | H34: Peter McLeod | I34: AUS | J34: Holden VL Commodore SS Group A | K34: 158 | L34: 3 | M34: 7h 1m 8.4s | O34: 139.82 km/h | P34: 8 | Q34: 86.88 mph
A35: 1988 | B35: Tooheys 1000 | D35: Tony Longhurst | E35: AUS | F35: Tomas Mezera | G35: AUS | J35: Ford Sierra RS500 | K35: 161 | M35: 7h 2m 10.28s | O35: 142.12 km/h | Q35: 88.31 mph
A36: 1989 | B36: Tooheys 1000 | D36: Dick Johnson | E36: AUS | F36: John Bowe | G36: AUS | J36: Ford Sierra RS500 | K36: 161 | M36: 6h 30m 53.44s | O36: 153.50 km/h | Q36: 95.38 mph
A37: 1990 | B37: Tooheys 1000 | D37: Win Percy | E37: GBR | F37: Allan Grice | G37: AUS | J37: Holden VL Commodore SS Group A SV | K37: 161 | M37: 6h 40m 52.64s | O37: 149.67 km/h | Q37: 93.00 mph
A38: 1991 | B38: Tooheys 1000 | D38: Jim Richards | E38: NZL | F38: Mark Skaife | G38: AUS | J38: Nissan Skyline BNR32 GT-R | K38: 161 | M38: 6h 19m 14.80s | O38: 158.21 km/h | Q38: 98.31 mph
A39: 1992 | B39: Tooheys 1000 | D39: Mark Skaife | E39: AUS | F39: Jim Richards | G39: NZL | J39: Nissan Skyline BNR32 GT-R | K39: 143 | L39: 2 | M39: 6h 27m 16.22s | O39: 137.61 km/h | Q39: 85.51 mph
A40: 1993 | B40: Tooheys 1000 | D40: Larry Perkins | E40: AUS | F40: Gregg Hansford | G40: AUS | J40: Holden VP Commodore | K40: 161 | M40: 6h 29m 6.69s | O40: 154.19 km/h | Q40: 95.81 mph
A41: 1994 | B41: Tooheys 1000 | D41: Dick Johnson | E41: AUS | F41: John Bowe | G41: AUS | J41: Ford EB Falcon | K41: 161 | M41: 7h 3m 45.8425s | O41: 141.5882 km/h | Q41: 87.9788 mph
...

Sheet Years Racing The Great Race
B1: 60 | C1: 61 | D1: 62 | E1: 63 | F1: 64 | G1: 65 | H1: 66 | I1: 67 | J1: 68 | K1: 69 | L1: 70 | M1: 71 | N1: 72 | O1: 73 | P1: 74 | Q1: 75 | R1: 76 | S1: 77 | T1: 78 | U1: 79 | V1: 80 | W1: 81 | X1: 82 | Y1: 83 | Z1: 84 | AA1: 85 | AB1: 86 | AC1: 87 | AD1: 88 | AE1: 89 | AF1: 90 | AG1: 91 | AH1: 92 | AI1: 93 | AJ1: 94 | AK1: 95 | AL1: 96 | AM1: 97 | AN1: 97 ST | AO1: 98 | AP1: 98 ST | AQ1: 99 | AR1: 99 ST | AS1: 00 | AT1: 01 | AU1: 02 | AV1: 03 | AW1: 04 | AX1: 05 | AY1: 06 | AZ1: 07 | BA1: 08 | BB1: 09 | BC1: 10 | BD1: 11 | BE1: 12 | BF1: 13 | BG1: 14 | BH1: 15 | BI1: 16 | BJ1: 17 | BK1: 18 | BL1: 19 | BM1: 20 | BN1: 21 | BO1: 22 | BP1: 23 | BQ1: 24 | BR1: 25 | BS1: 26 | BT1: Total | BV1: Surname | BW1: First
A2: Rauno Aaltonen | H2: 1 | AG2: 1 | BT2: =COUNTIF(B2:BS2,1) | BV2: =TRIM(RIGHT(A2, LEN(A2) - FIND("@", SUBSTITUTE(A2, " ", "@", LEN(A2)-LEN(SUBSTITUTE(A2," ","")))))) | BW2: =TRIM(LEFT(A2,FIND(" ",A2&" ")-1)) | BX2: =+IF(BV2=BV1,"Same","Diff") | BY2: =IF(BX2="Same",IF(BW2=BW1,"same","Diff"))
A3: Ern Abbott | B3: 1 | E3: 1 | G3: 1 | H3: 1 | BT3: =COUNTIF(B3:BS3,1) | BV3: =TRIM(RIGHT(A3, LEN(A3) - FIND("@", SUBSTITUTE(A3, " ", "@", LEN(A3)-LEN(SUBSTITUTE(A3," ","")))))) | BW3: =TRIM(LEFT(A3,FIND(" ",A3&" ")-1)) | BX3: =+IF(BV3=BV2,"Same","Diff") | BY3: =IF(BX3="Same",IF(BW3=BW2,"same","Diff"))
A4: Arthur Abrahams | AG4: 1 | BT4: =COUNTIF(B4:BS4,1) | BV4: =TRIM(RIGHT(A4, LEN(A4) - FIND("@", SUBSTITUTE(A4, " ", "@", LEN(A4)-LEN(SUBSTITUTE(A4," ","")))))) | BW4: =TRIM(LEFT(A4,FIND(" ",A4&" ")-1)) | BX4: =+IF(BV4=BV3,"Same","Diff") | BY4: =IF(BX4="Same",IF(BW4=BW3,"same","Diff"))
A5: Graeme Adams | P5: 1 | Q5: 1 | BT5: =COUNTIF(B5:BS5,1) | BV5: =TRIM(RIGHT(A5, LEN(A5) - FIND("@", SUBSTITUTE(A5, " ", "@", LEN(A5)-LEN(SUBSTITUTE(A5," ","")))))) | BW5: =TRIM(LEFT(A5,FIND(" ",A5&" ")-1)) | BX5: =+IF(BV5=BV4,"Same","Diff") | BY5: =IF(BX5="Same",IF(BW5=BW4,"same","Diff"))
A6: Lindsay Adcock | I6: 1 | J6: 1 | BT6: =COUNTIF(B6:BS6,1) | BV6: =TRIM(RIGHT(A6, LEN(A6) - FIND("@", SUBSTITUTE(A6, " ", "@", LEN(A6)-LEN(SUBSTITUTE(A6," ","")))))) | BW6: =TRIM(LEFT(A6,FIND(" ",A6&" ")-1)) | BX6: =+IF(BV6=BV5,"Same","Diff") | BY6: =IF(BX6="Same",IF(BW6=BW5,"same","Diff"))
A7: Michael Adcock | AE7: 1 | BT7: =COUNTIF(B7:BS7,1) | BV7: =TRIM(RIGHT(A7, LEN(A7) - FIND("@", SUBSTITUTE(A7, " ", "@", LEN(A7)-LEN(SUBSTITUTE(A7," ","")))))) | BW7: =TRIM(LEFT(A7,FIND(" ",A7&" ")-1)) | BX7: =+IF(BV7=BV6,"Same","Diff") | BY7: =IF(BX7="Same",IF(BW7=BW6,"same","Diff"))
A8: Arnold Ahrenfeld | F8: 1 | G8: 1 | BT8: =COUNTIF(B8:BS8,1) | BV8: =TRIM(RIGHT(A8, LEN(A8) - FIND("@", SUBSTITUTE(A8, " ", "@", LEN(A8)-LEN(SUBSTITUTE(A8," ","")))))) | BW8: =TRIM(LEFT(A8,FIND(" ",A8&" ")-1)) | BX8: =+IF(BV8=BV7,"Same","Diff") | BY8: =IF(BX8="Same",IF(BW8=BW7,"same","Diff"))
A9: John Ainsley | Q9: 1 | R9: 1 | BT9: =COUNTIF(B9:BS9,1) | BV9: =TRIM(RIGHT(A9, LEN(A9) - FIND("@", SUBSTITUTE(A9, " ", "@", LEN(A9)-LEN(SUBSTITUTE(A9," ","")))))) | BW9: =TRIM(LEFT(A9,FIND(" ",A9&" ")-1)) | BX9: =+IF(BV9=BV8,"Same","Diff") | BY9: =IF(BX9="Same",IF(BW9=BW8,"same","Diff"))
A10: John Alexander | E10: 1 | BT10: =COUNTIF(B10:BS10,1) | BV10: =TRIM(RIGHT(A10, LEN(A10) - FIND("@", SUBSTITUTE(A10, " ", "@", LEN(A10)-LEN(SUBSTITUTE(A10," ","")))))) | BW10: =TRIM(LEFT(A10,FIND(" ",A10&" ")-1)) | BX10: =+IF(BV10=BV9,"Same","Diff") | BY10: =IF(BX10="Same",IF(BW10=BW9,"same","Diff"))
A11: Phil Alexander | W11: 1 | X11: 1 | Y11: 1 | Z11: 1 | BT11: =COUNTIF(B11:BS11,1) | BV11: =TRIM(RIGHT(A11, LEN(A11) - FIND("@", SUBSTITUTE(A11, " ", "@", LEN(A11)-LEN(SUBSTITUTE(A11," ","")))))) | BW11: =TRIM(LEFT(A11,FIND(" ",A11&" ")-1)) | BX11: =+IF(BV11=BV10,"Same","Diff") | BY11: =IF(BX11="Same",IF(BW11=BW10,"same","Diff"))
A12: Don Algie | D12: 1 | BT12: =COUNTIF(B12:BS12,1) | BV12: =TRIM(RIGHT(A12, LEN(A12) - FIND("@", SUBSTITUTE(A12, " ", "@", LEN(A12)-LEN(SUBSTITUTE(A12," ","")))))) | BW12: =TRIM(LEFT(A12,FIND(" ",A12&" ")-1)) | BX12: =+IF(BV12=BV11,"Same","Diff") | BY12: =IF(BX12="Same",IF(BW12=BW11,"same","Diff"))
A13: Jeff Allam | Z13: 1 | AA13: 1 | AD13: 1 | AE13: 1 | AF13: 1 | AI13: 1 | AJ13: 1 | BT13: =COUNTIF(B13:BS13,1) | BV13: =TRIM(RIGHT(A13, LEN(A13) - FIND("@", SUBSTITUTE(A13, " ", "@", LEN(A13)-LEN(SUBSTITUTE(A13," ","")))))) | BW13: =TRIM(LEFT(A13,FIND(" ",A13&" ")-1)) | BX13: =+IF(BV13=BV12,"Same","Diff") | BY13: =IF(BX13="Same",IF(BW13=BW12,"same","Diff"))
A14: Barry Allen | Q14: 1 | BT14: =COUNTIF(B14:BS14,1) | BV14: =TRIM(RIGHT(A14, LEN(A14) - FIND("@", SUBSTITUTE(A14, " ", "@", LEN(A14)-LEN(SUBSTITUTE(A14," ","")))))) | BW14: =TRIM(LEFT(A14,FIND(" ",A14&" ")-1)) | BX14: =+IF(BV14=BV13,"Same","Diff") | BY14: =IF(BX14="Same",IF(BW14=BW13,"same","Diff"))
A15: Kai Allen | BP15: 1 | BQ15: 1 | BR15: 1 | BS15: 1 | BT15: =COUNTIF(B15:BS15,1) | BV15: =TRIM(RIGHT(A15, LEN(A15) - FIND("@", SUBSTITUTE(A15, " ", "@", LEN(A15)-LEN(SUBSTITUTE(A15," ","")))))) | BW15: =TRIM(LEFT(A15,FIND(" ",A15&" ")-1)) | BX15: =+IF(BV15=BV14,"Same","Diff") | BY15: =IF(BX15="Same",IF(BW15=BW14,"same","Diff"))
A16: Terry Allen | D16: 1 | BT16: =COUNTIF(B16:BS16,1) | BV16: =TRIM(RIGHT(A16, LEN(A16) - FIND("@", SUBSTITUTE(A16, " ", "@", LEN(A16)-LEN(SUBSTITUTE(A16," ","")))))) | BW16: =TRIM(LEFT(A16,FIND(" ",A16&" ")-1)) | BX16: =+IF(BV16=BV15,"Same","Diff") | BY16: =IF(BX16="Same",IF(BW16=BW15,"same","Diff"))
A17: Tony Allen | E17: 1 | F17: 1 | N17: 1 | O17: 1 | P17: 1 | BT17: =COUNTIF(B17:BS17,1) | BV17: =TRIM(RIGHT(A17, LEN(A17) - FIND("@", SUBSTITUTE(A17, " ", "@", LEN(A17)-LEN(SUBSTITUTE(A17," ","")))))) | BW17: =TRIM(LEFT(A17,FIND(" ",A17&" ")-1)) | BX17: =+IF(BV17=BV16,"Same","Diff") | BY17: =IF(BX17="Same",IF(BW17=BW16,"same","Diff"))
A18: Marcos Ambrose | AT18: 1 | AU18: 1 | AV18: 1 | AW18: 1 | AX18: 1 | BH18: 1 | BT18: =COUNTIF(B18:BS18,1) | BV18: =TRIM(RIGHT(A18, LEN(A18) - FIND("@", SUBSTITUTE(A18, " ", "@", LEN(A18)-LEN(SUBSTITUTE(A18," ","")))))) | BW18: =TRIM(LEFT(A18,FIND(" ",A18&" ")-1)) | BX18: =+IF(BV18=BV17,"Same","Diff") | BY18: =IF(BX18="Same",IF(BW18=BW17,"same","Diff"))
A19: John Amp | B19: 1 | BT19: =COUNTIF(B19:BS19,1) | BV19: =TRIM(RIGHT(A19, LEN(A19) - FIND("@", SUBSTITUTE(A19, " ", "@", LEN(A19)-LEN(SUBSTITUTE(A19," ","")))))) | BW19: =TRIM(LEFT(A19,FIND(" ",A19&" ")-1)) | BX19: =+IF(BV19=BV18,"Same","Diff") | BY19: =IF(BX19="Same",IF(BW19=BW18,"same","Diff"))
A20: Bruce Anderson | AA20: 1 | AB20: 1 | BT20: =COUNTIF(B20:BS20,1) | BV20: =TRIM(RIGHT(A20, LEN(A20) - FIND("@", SUBSTITUTE(A20, " ", "@", LEN(A20)-LEN(SUBSTITUTE(A20," ","")))))) | BW20: =TRIM(LEFT(A20,FIND(" ",A20&" ")-1)) | BX20: =+IF(BV20=BV19,"Same","Diff") | BY20: =IF(BX20="Same",IF(BW20=BW19,"same","Diff"))
A21: David Anderson | B21: 1 | D21: 1 | BT21: =COUNTIF(B21:BS21,1) | BV21: =TRIM(RIGHT(A21, LEN(A21) - FIND("@", SUBSTITUTE(A21, " ", "@", LEN(A21)-LEN(SUBSTITUTE(A21," ","")))))) | BW21: =TRIM(LEFT(A21,FIND(" ",A21&" ")-1)) | BX21: =+IF(BV21=BV20,"Same","Diff") | BY21: =IF(BX21="Same",IF(BW21=BW20,"same","Diff"))
A22: Jack Anderson | D22: 1 | BT22: =COUNTIF(B22:BS22,1) | BV22: =TRIM(RIGHT(A22, LEN(A22) - FIND("@", SUBSTITUTE(A22, " ", "@", LEN(A22)-LEN(SUBSTITUTE(A22," ","")))))) | BW22: =TRIM(LEFT(A22,FIND(" ",A22&" ")-1)) | BX22: =+IF(BV22=BV21,"Same","Diff") | BY22: =IF(BX22="Same",IF(BW22=BW21,"same","Diff"))
A23: Wayne Anderson | AA23: 1 | AB23: 1 | BT23: =COUNTIF(B23:BS23,1) | BV23: =TRIM(RIGHT(A23, LEN(A23) - FIND("@", SUBSTITUTE(A23, " ", "@", LEN(A23)-LEN(SUBSTITUTE(A23," ","")))))) | BW23: =TRIM(LEFT(A23,FIND(" ",A23&" ")-1)) | BX23: =+IF(BV23=BV22,"Same","Diff") | BY23: =IF(BX23="Same",IF(BW23=BW22,"same","Diff"))
A24: John Andretti | AD24: 1 | BT24: =COUNTIF(B24:BS24,1) | BV24: =TRIM(RIGHT(A24, LEN(A24) - FIND("@", SUBSTITUTE(A24, " ", "@", LEN(A24)-LEN(SUBSTITUTE(A24," ","")))))) | BW24: =TRIM(LEFT(A24,FIND(" ",A24&" ")-1)) | BX24: =+IF(BV24=BV23,"Same","Diff") | BY24: =IF(BX24="Same",IF(BW24=BW23,"same","Diff"))
A25: Arthur Andrews | E25: 1 | BT25: =COUNTIF(B25:BS25,1) | BV25: =TRIM(RIGHT(A25, LEN(A25) - FIND("@", SUBSTITUTE(A25, " ", "@", LEN(A25)-LEN(SUBSTITUTE(A25," ","")))))) | BW25: =TRIM(LEFT(A25,FIND(" ",A25&" ")-1)) | BX25: =+IF(BV25=BV24,"Same","Diff") | BY25: =IF(BX25="Same",IF(BW25=BW24,"same","Diff"))
A26: Doug Angus | R26: 1 | BT26: =COUNTIF(B26:BS26,1) | BV26: =TRIM(RIGHT(A26, LEN(A26) - FIND("@", SUBSTITUTE(A26, " ", "@", LEN(A26)-LEN(SUBSTITUTE(A26," ","")))))) | BW26: =TRIM(LEFT(A26,FIND(" ",A26&" ")-1)) | BX26: =+IF(BV26=BV25,"Same","Diff") | BY26: =IF(BX26="Same",IF(BW26=BW25,"same","Diff"))
A27: Barry Arentz | G27: 1 | H27: 1 | J27: 1 | K27: 1 | M27: 1 | BT27: =COUNTIF(B27:BS27,1) | BV27: =TRIM(RIGHT(A27, LEN(A27) - FIND("@", SUBSTITUTE(A27, " ", "@", LEN(A27)-LEN(SUBSTITUTE(A27," ","")))))) | BW27: =TRIM(LEFT(A27,FIND(" ",A27&" ")-1)) | BX27: =+IF(BV27=BV26,"Same","Diff") | BY27: =IF(BX27="Same",IF(BW27=BW26,"same","Diff"))
A28: Greville Arnel | R28: 1 | T28: 1 | Z28: 1 | AA28: 1 | BT28: =COUNTIF(B28:BS28,1) | BV28: =TRIM(RIGHT(A28, LEN(A28) - FIND("@", SUBSTITUTE(A28, " ", "@", LEN(A28)-LEN(SUBSTITUTE(A28," ","")))))) | BW28: =TRIM(LEFT(A28,FIND(" ",A28&" ")-1)) | BX28: =+IF(BV28=BV27,"Same","Diff") | BY28: =IF(BX28="Same",IF(BW28=BW27,"same","Diff"))
A29: Lyndon Arnel | N29: 1 | O29: 1 | P29: 1 | Q29: 1 | R29: 1 | S29: 1 | T29: 1 | Z29: 1 | BT29: =COUNTIF(B29:BS29,1) | BV29: =TRIM(RIGHT(A29, LEN(A29) - FIND("@", SUBSTITUTE(A29, " ", "@", LEN(A29)-LEN(SUBSTITUTE(A29," ","")))))) | BW29: =TRIM(LEFT(A29,FIND(" ",A29&" ")-1)) | BX29: =+IF(BV29=BV28,"Same","Diff") | BY29: =IF(BX29="Same",IF(BW29=BW28,"same","Diff"))
A30: Phillip Arnull | O30: 1 | S30: 1 | T30: 1 | BT30: =COUNTIF(B30:BS30,1) | BV30: =TRIM(RIGHT(A30, LEN(A30) - FIND("@", SUBSTITUTE(A30, " ", "@", LEN(A30)-LEN(SUBSTITUTE(A30," ","")))))) | BW30: =TRIM(LEFT(A30,FIND(" ",A30&" ")-1)) | BX30: =+IF(BV30=BV29,"Same","Diff") | BY30: =IF(BX30="Same",IF(BW30=BW29,"same","Diff"))
A31: Trevor Ashby | AB31: 1 | AC31: 1 | AD31: 1 | AE31: 1 | AF31: 1 | AG31: 1 | AH31: 1 | AI31: 1 | AJ31: 1 | AK31: 1 | AL31: 1 | AM31: 1 | AO31: 1 | AQ31: 1 | AS31: 1 | AT31: 1 | BT31: =COUNTIF(B31:BS31,1) | BV31: =TRIM(RIGHT(A31, LEN(A31) - FIND("@", SUBSTITUTE(A31, " ", "@", LEN(A31)-LEN(SUBSTITUTE(A31," ","")))))) | BW31: =TRIM(LEFT(A31,FIND(" ",A31&" ")-1)) | BX31: =+IF(BV31=BV30,"Same","Diff") | BY31: =IF(BX31="Same",IF(BW31=BW30,"same","Diff"))
A32: Damian Assaillit | BB32: 1 | BC32: 1 | BT32: =COUNTIF(B32:BS32,1) | BV32: =TRIM(RIGHT(A32, LEN(A32) - FIND("@", SUBSTITUTE(A32, " ", "@", LEN(A32)-LEN(SUBSTITUTE(A32," ","")))))) | BW32: =TRIM(LEFT(A32,FIND(" ",A32&" ")-1)) | BX32: =+IF(BV32=BV31,"Same","Diff") | BY32: =IF(BX32="Same",IF(BW32=BW31,"same","Diff"))
